<?xml version="1.0" ?>
<robot name="simple_humanoid" xmlns:xacro="http://www.ros.org/wiki/xacro">
  <!-- Materials -->
  <material name="black">
    <color rgba="0.0 0.0 0.0 1.0"/>
  </material>
  <material name="blue">
    <color rgba="0.0 0.0 0.8 1.0"/>
  </material>
  <material name="green">
    <color rgba="0.0 0.8 0.0 1.0"/>
  </material>
  <material name="grey">
    <color rgba="0.5 0.5 0.5 1.0"/>
  </material>
  <material name="orange">
    <color rgba="1.0 0.423529411765 0.0392156862745 1.0"/>
  </material>
  <material name="brown">
    <color rgba="0.870588235294 0.811764705882 0.764705882353 1.0"/>
  </material>
  <material name="red">
    <color rgba="0.8 0.0 0.0 1.0"/>
  </material>
  <material name="white">
    <color rgba="1.0 1.0 1.0 1.0"/>
  </material>

  <!-- Base link -->
  <link name="base_link">
    <visual>
      <geometry>
        <box size="0.1 0.1 0.1"/>
      </geometry>
      <material name="white"/>
    </visual>
    <collision>
      <geometry>
        <box size="0.1 0.1 0.1"/>
      </geometry>
    </collision>
    <inertial>
      <mass value="1.0"/>
      <inertia ixx="0.01" ixy="0.0" ixz="0.0" iyy="0.01" iyz="0.0" izz="0.01"/>
    </inertial>
  </link>

  <!-- Torso -->
  <joint name="base_to_torso" type="fixed">
    <parent link="base_link"/>
    <child link="torso"/>
    <origin xyz="0 0 0.3" rpy="0 0 0"/>
  </joint>

  <link name="torso">
    <visual>
      <origin xyz="0 0 0.3" rpy="0 0 0"/>
      <geometry>
        <box size="0.3 0.2 0.6"/>
      </geometry>
      <material name="grey"/>
    </visual>
    <collision>
      <origin xyz="0 0 0.3" rpy="0 0 0"/>
      <geometry>
        <box size="0.3 0.2 0.6"/>
      </geometry>
    </collision>
    <inertial>
      <origin xyz="0 0 0.3" rpy="0 0 0"/>
      <mass value="10.0"/>
      <inertia ixx="0.5" ixy="0.0" ixz="0.0" iyy="0.6" iyz="0.0" izz="0.2"/>
    </inertial>
  </link>

  <!-- Head -->
  <joint name="torso_to_head" type="revolute">
    <parent link="torso"/>
    <child link="head"/>
    <origin xyz="0 0 0.6" rpy="0 0 0"/>
    <axis xyz="0 0 1"/>
    <limit lower="-1.57" upper="1.57" effort="10.0" velocity="1.0"/>
  </joint>

  <link name="head">
    <visual>
      <origin xyz="0 0 0.1" rpy="0 0 0"/>
      <geometry>
        <sphere radius="0.1"/>
      </geometry>
      <material name="white"/>
    </visual>
    <collision>
      <origin xyz="0 0 0.1" rpy="0 0 0"/>
      <geometry>
        <sphere radius="0.1"/>
      </geometry>
    </collision>
    <inertial>
      <origin xyz="0 0 0.1" rpy="0 0 0"/>
      <mass value="2.0"/>
      <inertia ixx="0.02" ixy="0.0" ixz="0.0" iyy="0.02" iyz="0.0" izz="0.02"/>
    </inertial>
  </link>

  <!-- Left Arm -->
  <joint name="left_shoulder_pan_joint" type="revolute">
    <parent link="torso"/>
    <child link="left_shoulder"/>
    <origin xyz="0.15 0.1 0.4" rpy="0 0 0"/>
    <axis xyz="0 0 1"/>
    <limit lower="-1.57" upper="1.57" effort="50.0" velocity="1.0"/>
  </joint>

  <link name="left_shoulder">
    <visual>
      <geometry>
        <cylinder radius="0.05" length="0.1"/>
      </geometry>
      <material name="white"/>
    </visual>
    <collision>
      <geometry>
        <cylinder radius="0.05" length="0.1"/>
      </geometry>
    </collision>
    <inertial>
      <mass value="0.5"/>
      <inertia ixx="0.001" ixy="0.0" ixz="0.0" iyy="0.001" iyz="0.0" izz="0.0005"/>
    </inertial>
  </link>

  <joint name="left_shoulder_lift_joint" type="revolute">
    <parent link="left_shoulder"/>
    <child link="left_upper_arm"/>
    <origin xyz="0.0 0.0 0.05" rpy="0 0 0"/>
    <axis xyz="0 1 0"/>
    <limit lower="-2.0" upper="2.0" effort="50.0" velocity="1.0"/>
  </joint>

  <link name="left_upper_arm">
    <visual>
      <origin xyz="0 0 0.15" rpy="0 0 0"/>
      <geometry>
        <cylinder radius="0.05" length="0.3"/>
      </geometry>
      <material name="white"/>
    </visual>
    <collision>
      <origin xyz="0 0 0.15" rpy="0 0 0"/>
      <geometry>
        <cylinder radius="0.05" length="0.3"/>
      </geometry>
    </collision>
    <inertial>
      <origin xyz="0 0 0.15" rpy="0 0 0"/>
      <mass value="1.0"/>
      <inertia ixx="0.01" ixy="0.0" ixz="0.0" iyy="0.01" iyz="0.0" izz="0.0025"/>
    </inertial>
  </link>

  <joint name="left_elbow_joint" type="revolute">
    <parent link="left_upper_arm"/>
    <child link="left_forearm"/>
    <origin xyz="0.0 0.0 0.3" rpy="0 0 0"/>
    <axis xyz="0 1 0"/>
    <limit lower="-2.5" upper="2.5" effort="50.0" velocity="1.0"/>
  </joint>

  <link name="left_forearm">
    <visual>
      <origin xyz="0 0 0.125" rpy="0 0 0"/>
      <geometry>
        <cylinder radius="0.04" length="0.25"/>
      </geometry>
      <material name="white"/>
    </visual>
    <collision>
      <origin xyz="0 0 0.125" rpy="0 0 0"/>
      <geometry>
        <cylinder radius="0.04" length="0.25"/>
      </geometry>
    </collision>
    <inertial>
      <origin xyz="0 0 0.125" rpy="0 0 0"/>
      <mass value="0.8"/>
      <inertia ixx="0.005" ixy="0.0" ixz="0.0" iyy="0.005" iyz="0.0" izz="0.001"/>
    </inertial>
  </link>

  <!-- Right Arm (mirror of left arm) -->
  <joint name="right_shoulder_pan_joint" type="revolute">
    <parent link="torso"/>
    <child link="right_shoulder"/>
    <origin xyz="0.15 -0.1 0.4" rpy="0 0 0"/>
    <axis xyz="0 0 1"/>
    <limit lower="-1.57" upper="1.57" effort="50.0" velocity="1.0"/>
  </joint>

  <link name="right_shoulder">
    <visual>
      <geometry>
        <cylinder radius="0.05" length="0.1"/>
      </geometry>
      <material name="white"/>
    </visual>
    <collision>
      <geometry>
        <cylinder radius="0.05" length="0.1"/>
      </geometry>
    </collision>
    <inertial>
      <mass value="0.5"/>
      <inertia ixx="0.001" ixy="0.0" ixz="0.0" iyy="0.001" iyz="0.0" izz="0.0005"/>
    </inertial>
  </link>

  <joint name="right_shoulder_lift_joint" type="revolute">
    <parent link="right_shoulder"/>
    <child link="right_upper_arm"/>
    <origin xyz="0.0 0.0 0.05" rpy="0 0 0"/>
    <axis xyz="0 1 0"/>
    <limit lower="-2.0" upper="2.0" effort="50.0" velocity="1.0"/>
  </joint>

  <link name="right_upper_arm">
    <visual>
      <origin xyz="0 0 0.15" rpy="0 0 0"/>
      <geometry>
        <cylinder radius="0.05" length="0.3"/>
      </geometry>
      <material name="white"/>
    </visual>
    <collision>
      <origin xyz="0 0 0.15" rpy="0 0 0"/>
      <geometry>
        <cylinder radius="0.05" length="0.3"/>
      </geometry>
    </collision>
    <inertial>
      <origin xyz="0 0 0.15" rpy="0 0 0"/>
      <mass value="1.0"/>
      <inertia ixx="0.01" ixy="0.0" ixz="0.0" iyy="0.01" iyz="0.0" izz="0.0025"/>
    </inertial>
  </link>

  <joint name="right_elbow_joint" type="revolute">
    <parent link="right_upper_arm"/>
    <child link="right_forearm"/>
    <origin xyz="0.0 0.0 0.3" rpy="0 0 0"/>
    <axis xyz="0 1 0"/>
    <limit lower="-2.5" upper="2.5" effort="50.0" velocity="1.0"/>
  </joint>

  <link name="right_forearm">
    <visual>
      <origin xyz="0 0 0.125" rpy="0 0 0"/>
      <geometry>
        <cylinder radius="0.04" length="0.25"/>
      </geometry>
      <material name="white"/>
    </visual>
    <collision>
      <origin xyz="0 0 0.125" rpy="0 0 0"/>
      <geometry>
        <cylinder radius="0.04" length="0.25"/>
      </geometry>
    </collision>
    <inertial>
      <origin xyz="0 0 0.125" rpy="0 0 0"/>
      <mass value="0.8"/>
      <inertia ixx="0.005" ixy="0.0" ixz="0.0" iyy="0.005" iyz="0.0" izz="0.001"/>
    </inertial>
  </link>

  <!-- Left Leg -->
  <joint name="left_hip_joint" type="revolute">
    <parent link="torso"/>
    <child link="left_thigh"/>
    <origin xyz="-0.1 0.05 0.0" rpy="0 0 0"/>
    <axis xyz="0 1 0"/>
    <limit lower="-1.57" upper="1.57" effort="100.0" velocity="1.0"/>
  </joint>

  <link name="left_thigh">
    <visual>
      <origin xyz="0 0 -0.2" rpy="0 0 0"/>
      <geometry>
        <cylinder radius="0.06" length="0.4"/>
      </geometry>
      <material name="white"/>
    </visual>
    <collision>
      <origin xyz="0 0 -0.2" rpy="0 0 0"/>
      <geometry>
        <cylinder radius="0.06" length="0.4"/>
      </geometry>
    </collision>
    <inertial>
      <origin xyz="0 0 -0.2" rpy="0 0 0"/>
      <mass value="2.0"/>
      <inertia ixx="0.04" ixy="0.0" ixz="0.0" iyy="0.04" iyz="0.0" izz="0.01"/>
    </inertial>
  </link>

  <joint name="left_knee_joint" type="revolute">
    <parent link="left_thigh"/>
    <child link="left_shin"/>
    <origin xyz="0.0 0.0 -0.4" rpy="0 0 0"/>
    <axis xyz="0 1 0"/>
    <limit lower="-2.0" upper="0.5" effort="100.0" velocity="1.0"/>
  </joint>

  <link name="left_shin">
    <visual>
      <origin xyz="0 0 -0.2" rpy="0 0 0"/>
      <geometry>
        <cylinder radius="0.05" length="0.4"/>
      </geometry>
      <material name="white"/>
    </visual>
    <collision>
      <origin xyz="0 0 -0.2" rpy="0 0 0"/>
      <geometry>
        <cylinder radius="0.05" length="0.4"/>
      </geometry>
    </collision>
    <inertial>
      <origin xyz="0 0 -0.2" rpy="0 0 0"/>
      <mass value="1.5"/>
      <inertia ixx="0.03" ixy="0.0" ixz="0.0" iyy="0.03" iyz="0.0" izz="0.008"/>
    </inertial>
  </link>

  <!-- Right Leg (mirror of left leg) -->
  <joint name="right_hip_joint" type="revolute">
    <parent link="torso"/>
    <child link="right_thigh"/>
    <origin xyz="-0.1 -0.05 0.0" rpy="0 0 0"/>
    <axis xyz="0 1 0"/>
    <limit lower="-1.57" upper="1.57" effort="100.0" velocity="1.0"/>
  </joint>

  <link name="right_thigh">
    <visual>
      <origin xyz="0 0 -0.2" rpy="0 0 0"/>
      <geometry>
        <cylinder radius="0.06" length="0.4"/>
      </geometry>
      <material name="white"/>
    </visual>
    <collision>
      <origin xyz="0 0 -0.2" rpy="0 0 0"/>
      <geometry>
        <cylinder radius="0.06" length="0.4"/>
      </geometry>
    </collision>
    <inertial>
      <origin xyz="0 0 -0.2" rpy="0 0 0"/>
      <mass value="2.0"/>
      <inertia ixx="0.04" ixy="0.0" ixz="0.0" iyy="0.04" iyz="0.0" izz="0.01"/>
    </inertial>
  </link>

  <joint name="right_knee_joint" type="revolute">
    <parent link="right_thigh"/>
    <child link="right_shin"/>
    <origin xyz="0.0 0.0 -0.4" rpy="0 0 0"/>
    <axis xyz="0 1 0"/>
    <limit lower="-2.0" upper="0.5" effort="100.0" velocity="1.0"/>
  </joint>

  <link name="right_shin">
    <visual>
      <origin xyz="0 0 -0.2" rpy="0 0 0"/>
      <geometry>
        <cylinder radius="0.05" length="0.4"/>
      </geometry>
      <material name="white"/>
    </visual>
    <collision>
      <origin xyz="0 0 -0.2" rpy="0 0 0"/>
      <geometry>
        <cylinder radius="0.05" length="0.4"/>
      </geometry>
    </collision>
    <inertial>
      <origin xyz="0 0 -0.2" rpy="0 0 0"/>
      <mass value="1.5"/>
      <inertia ixx="0.03" ixy="0.0" ixz="0.0" iyy="0.03" iyz="0.0" izz="0.008"/>
    </inertial>
  </link>
</robot>